python3: can't open file 'add_generated_notes.py': [Errno 2] No such file or directory
